Workbook

Sheet Phase Planning
J2: SM2 Alg
B3: Article ID | C3: Content | D3: Interest 1 | E3: Interest 2 | F3: Interest 3 | G3: SM2 Tag | J3: 1 | K3: Fruits
B4: 1 | C4: Cooking Video | D4: Food | E4: Italian | G4: Food | J4: 2 | K4: Location
B5: 2 | C5: Travel Vlog | D5: Location | E5: Food | G5: Location | J5: 3 | K5: Season
B6: 3 | C6: Story time with dog | D6: mood | E6: animal | F6: Location | G6: Mood | J6: 4 | K6: Mood
B7: 4 | C7: History educational content | D7: Location | E7: History | G7: Past/Present/Future | J7: 5 | K7: Plants
J8: 6 | K8: Animals
J9: 7 | K9: Kitchen
J10: 8 | K10: Past/Present/Future
B13: Phase 1
B14: Current | C14: Articles and Translated | N14: Elo System
B15: 1 | C15: Frequency Dictionary | D15: Database of Frequency Dictionary | E15: Catorgoried with Tags | G15: Issac, Milan, Alex | N15: First 10 | O15: Rank
B16: 2 | C16: Quizes interact with DB | D16: criteria of a good quiz | E16: Make a prompt for quiz generation | J16: Novice | K16: 0
B17: 3 | C17: Impliment Quiz into product | J17: Beg | K17: 300
J18: Inter | K18: 600
B19: 4 | C19: Quizes with articles with key words with SM2 Algorithmn | J19: Pro | K19: 1000
B21: Key Dev
C22: Cost effective AI models
C23: Linking Frequency table to articles | F23: 3 | G23: 0.65 | H23: =F23*G23 -> 1.95
C24: Quiz to AI Model, cost effective, w prompt with article ID | D24: Click on article -> Starts prompt on Quiz | F24: 2 | G24: 0.35 | H24: =F24*G24 -> 0.7
C25: Elo based system quizes profile | D25: Milan and Issac Architecture | E25: Starting elo | F25: 300
E26: plus quiz | H26: =SUM(H23:H24) -> 2.65
E27: Beg | F27: 10
E28: Adv | F28: 30
B31: Phase 2 | C31: Quiz talks to SM2 based on Score | E31: Spanish, French, Japanese, Korean, and German
C32: Dialects

Sheet Words
A2: Wordopedia | B2: rank | C2: word | D2: absolute frequency | E2: lemma forms | I2: Word Dictionary | J2: https://wortschatz.uni-leipzig.de/en/download/spa
B4: 101 | C4: de | D4: 15226 | I4: The Leipzig Corpora Collection (University of Leipzig) is highly credible and considered one of the premier resources in the field of computational linguistics. Within academic and data science circles, it is a standard source for word frequency data.
B5: 102 | C5: la | D5: 7493
B6: 103 | C6: en | D6: 5973 | I6: University of Leipzig
B7: 104 | C7: el | D7: 5435
B8: 105 | C8: y | D8: 5422
B9: 106 | C9: que | D9: 4171
B10: 107 | C10: a | D10: 3844 | J10: CATEGORYS
B11: 108 | C11: se | D11: 2845
B12: 109 | C12: los | D12: 2800 | J12: Category ID | K12: Category Name
B13: 110 | C13: del | D13: 2645 | J13: 1 | K13: Politics & Government
B14: 111 | C14: un | D14: 2205 | J14: 2 | K14: Economics & Business
B15: 112 | C15: su | D15: 2051 | J15: 3 | K15: Arts, Culture & Entertainment
B16: 113 | C16: una | D16: 2023 | J16: 4 | K16: Sports
B17: 114 | C17: con | D17: 2014 | J17: 5 | K17: Science, Technology & Health
B18: 115 | C18: las | D18: 1946 | J18: 6 | K18: Geography & Nature
B19: 116 | C19: por | D19: 1899 | J19: 7 | K19: Education & Research
B20: 117 | C20: para | D20: 1498 | J20: 8 | K20: Law & Security
B21: 118 | C21: es | D21: 1206 | J21: 9 | K21: Religion & History
B22: 119 | C22: El | D22: 1182
B23: 120 | C23: como | D23: 1140
B24: 121 | C24: al | D24: 1055
B25: 122 | C25: En | D25: 999
B26: 123 | C26: fue | D26: 944
B27: 124 | C27: no | D27: 891
B28: 125 | C28: La | D28: 879
B29: 126 | C29: más | D29: 855
B30: 127 | C30: sus | D30: 663
B31: 128 | C31: lo | D31: 652
B32: 129 | C32: o | D32: 458
B33: 130 | C33: también | D33: 390
... B182: 279 | C182: zona | D182: 81
B183: 280 | C183: 10 | D183: 80
B184: 281 | C184: Cuando | D184: 80
B185: 282 | C185: San | D185: 80
B186: 283 | C186: además | D186: 80
B187: 284 | C187: dentro | D187: 80
B188: 285 | C188: mayoría | D188: 80
B189: 286 | C189: muchos | D189: 80
B190: 287 | C190: poco | D190: 80
...

Sheet Sheet3
B2: Wordopedia | C2: WORD ID | D2: word | E2: absolute frequency | F2: CAT ID | G2: LEVEL ID | J2: Word Dictionary | K2: https://wortschatz.uni-leipzig.de/en/download/spa
C4: 1 | D4: de | E4: 15226 | F4: =_xlfn.XLOOKUP(D4,'Gemini Output'!B:B,'Gemini Output'!C:C,"No Match Yet") -> 1 | G4: =_xlfn.XLOOKUP(D4,'Gemini Output'!B:B,'Gemini Output'!E:E,"No Match Yet") -> L1 | J4: The Leipzig Corpora Collection (University of Leipzig) is highly credible and considered one of the premier resources in the field of computational linguistics. Within academic and data science circles, it is a standard source for word frequency data.
C5: 2 | D5: la | E5: 7493 | F5: =_xlfn.XLOOKUP(D5,'Gemini Output'!B:B,'Gemini Output'!C:C,"No Match Yet") -> 12 | G5: =_xlfn.XLOOKUP(D5,'Gemini Output'!B:B,'Gemini Output'!E:E,"No Match Yet") -> L1
C6: 3 | D6: en | E6: 5973 | F6: =_xlfn.XLOOKUP(D6,'Gemini Output'!B:B,'Gemini Output'!C:C,"No Match Yet") -> 10 | G6: =_xlfn.XLOOKUP(D6,'Gemini Output'!B:B,'Gemini Output'!E:E,"No Match Yet") -> L1 | J6: University of Leipzig
C7: 4 | D7: el | E7: 5435 | F7: =_xlfn.XLOOKUP(D7,'Gemini Output'!B:B,'Gemini Output'!C:C,"No Match Yet") -> 12 | G7: =_xlfn.XLOOKUP(D7,'Gemini Output'!B:B,'Gemini Output'!E:E,"No Match Yet") -> L1
C8: 5 | D8: y | E8: 5422 | F8: =_xlfn.XLOOKUP(D8,'Gemini Output'!B:B,'Gemini Output'!C:C,"No Match Yet") -> 12 | G8: =_xlfn.XLOOKUP(D8,'Gemini Output'!B:B,'Gemini Output'!E:E,"No Match Yet") -> L1
C9: 6 | D9: que | E9: 4171 | F9: =_xlfn.XLOOKUP(D9,'Gemini Output'!B:B,'Gemini Output'!C:C,"No Match Yet") -> 12 | G9: =_xlfn.XLOOKUP(D9,'Gemini Output'!B:B,'Gemini Output'!E:E,"No Match Yet") -> L1 | J9: CAT ID | K9: Category Name | L9: Quiz "Vibe" for the AI | R9: CAT ID | S9: COUNT of Filter | T9: Level Break down
C10: 7 | D10: a | E10: 3844 | F10: =_xlfn.XLOOKUP(D10,'Gemini Output'!B:B,'Gemini Output'!C:C,"No Match Yet") -> 13 | G10: =_xlfn.XLOOKUP(D10,'Gemini Output'!B:B,'Gemini Output'!E:E,"No Match Yet") -> L1 | J10: 1 | K10: Politics & Government | L10: Fact-based (Who, what law, which year?) | R10: 1 | S10: =COUNTIF(F:F,R10) -> 96 | T10: L1 | U10: =COUNTIF(G:G,T10) -> 452 | V10: =U10/1000 -> 0.452
C11: 8 | D11: se | E11: 2845 | F11: =_xlfn.XLOOKUP(D11,'Gemini Output'!B:B,'Gemini Output'!C:C,"No Match Yet") -> 12 | G11: =_xlfn.XLOOKUP(D11,'Gemini Output'!B:B,'Gemini Output'!E:E,"No Match Yet") -> L1 | J11: 2 | K11: Economy & Finance | L11: Logical/Numerical (Prices, growth, trends) | R11: 2 | S11: =COUNTIF(F:F,R11) -> 54 | T11: L2 | U11: =COUNTIF(G:G,T11) -> 486 | V11: =U11/1000 -> 0.486
C12: 9 | D12: los | E12: 2800 | F12: =_xlfn.XLOOKUP(D12,'Gemini Output'!B:B,'Gemini Output'!C:C,"No Match Yet") -> 12 | G12: =_xlfn.XLOOKUP(D12,'Gemini Output'!B:B,'Gemini Output'!E:E,"No Match Yet") -> L1 | J12: 3 | K12: Arts & Entertainment | L12: Creative/Recall (Names, works, dates) | R12: 3 | S12: =COUNTIF(F:F,R12) -> 67 | T12: L3 | U12: =COUNTIF(G:G,T12) -> 62 | V12: =U12/1000 -> 0.062
C13: 10 | D13: del | E13: 2645 | F13: =_xlfn.XLOOKUP(D13,'Gemini Output'!B:B,'Gemini Output'!C:C,"No Match Yet") -> 1 | G13: =_xlfn.XLOOKUP(D13,'Gemini Output'!B:B,'Gemini Output'!E:E,"No Match Yet") -> L1 | J13: 4 | K13: Sports | L13: Statistic/Outcome (Scores, teams, events) | R13: 4 | S13: =COUNTIF(F:F,R13) -> 46
C14: 11 | D14: un | E14: 2205 | F14: =_xlfn.XLOOKUP(D14,'Gemini Output'!B:B,'Gemini Output'!C:C,"No Match Yet") -> 12 | G14: =_xlfn.XLOOKUP(D14,'Gemini Output'!B:B,'Gemini Output'!E:E,"No Match Yet") -> L1 | J14: 5 | K14: Business & Labor | L14: Operational (Company names, hiring, trade) | R14: 5 | S14: =COUNTIF(F:F,R14) -> 59
C15: 12 | D15: su | E15: 2051 | F15: =_xlfn.XLOOKUP(D15,'Gemini Output'!B:B,'Gemini Output'!C:C,"No Match Yet") -> 5 | G15: =_xlfn.XLOOKUP(D15,'Gemini Output'!B:B,'Gemini Output'!E:E,"No Match Yet") -> L1 | J15: 6 | K15: Science & Tech | L15: Conceptual (How it works, discovery) | R15: 6 | S15: =COUNTIF(F:F,R15) -> 79
C16: 13 | D16: una | E16: 2023 | F16: =_xlfn.XLOOKUP(D16,'Gemini Output'!B:B,'Gemini Output'!C:C,"No Match Yet") -> 12 | G16: =_xlfn.XLOOKUP(D16,'Gemini Output'!B:B,'Gemini Output'!E:E,"No Match Yet") -> L1 | J16: 7 | K16: Education | L16: Institutional (Degrees, academic research) | R16: 7 | S16: =COUNTIF(F:F,R16) -> 44
C17: 14 | D17: con | E17: 2014 | F17: =_xlfn.XLOOKUP(D17,'Gemini Output'!B:B,'Gemini Output'!C:C,"No Match Yet") -> 12 | G17: =_xlfn.XLOOKUP(D17,'Gemini Output'!B:B,'Gemini Output'!E:E,"No Match Yet") -> L1 | J17: 8 | K17: Crime, Law & Justice | L17: Narrative (What happened, what was the ruling?) | R17: 8 | S17: =COUNTIF(F:F,R17) -> 41
C18: 15 | D18: las | E18: 1946 | F18: =_xlfn.XLOOKUP(D18,'Gemini Output'!B:B,'Gemini Output'!C:C,"No Match Yet") -> 12 | G18: =_xlfn.XLOOKUP(D18,'Gemini Output'!B:B,'Gemini Output'!E:E,"No Match Yet") -> L1 | J18: 9 | K18: History & Religion | L18: Chronological (Timeline, cultural impact) | R18: 9 | S18: =COUNTIF(F:F,R18) -> 118
C19: 16 | D19: por | E19: 1899 | F19: =_xlfn.XLOOKUP(D19,'Gemini Output'!B:B,'Gemini Output'!C:C,"No Match Yet") -> 8 | G19: =_xlfn.XLOOKUP(D19,'Gemini Output'!B:B,'Gemini Output'!E:E,"No Match Yet") -> L1 | J19: 10 | K19: Environment & Nature | L19: Descriptive (Locations, ecological impact) | R19: 10 | S19: =COUNTIF(F:F,R19) -> 59
C20: 17 | D20: para | E20: 1498 | F20: =_xlfn.XLOOKUP(D20,'Gemini Output'!B:B,'Gemini Output'!C:C,"No Match Yet") -> 5 | G20: =_xlfn.XLOOKUP(D20,'Gemini Output'!B:B,'Gemini Output'!E:E,"No Match Yet") -> L1 | J20: 11 | K20: Health & Wellness | L20: Practical (Body parts, medical advice) | R20: 11 | S20: =COUNTIF(F:F,R20) -> 23
C21: 18 | D21: es | E21: 1206 | F21: =_xlfn.XLOOKUP(D21,'Gemini Output'!B:B,'Gemini Output'!C:C,"No Match Yet") -> 1 | G21: =_xlfn.XLOOKUP(D21,'Gemini Output'!B:B,'Gemini Output'!E:E,"No Match Yet") -> L1 | J21: 12 | K21: Social Issues/Society | L21: Sociological (Social groups, demographic trends) | R21: 12 | S21: =COUNTIF(F:F,R21) -> 169
C22: 19 | D22: El | E22: 1182 | F22: =_xlfn.XLOOKUP(D22,'Gemini Output'!B:B,'Gemini Output'!C:C,"No Match Yet") -> 12 | G22: =_xlfn.XLOOKUP(D22,'Gemini Output'!B:B,'Gemini Output'!E:E,"No Match Yet") -> L1 | J22: 13 | K22: Lifestyle & Travel | L22: Experiential (Destination names, habits) | R22: 13 | S22: =COUNTIF(F:F,R22) -> 83
C23: 20 | D23: como | E23: 1140 | F23: =_xlfn.XLOOKUP(D23,'Gemini Output'!B:B,'Gemini Output'!C:C,"No Match Yet") -> 12 | G23: =_xlfn.XLOOKUP(D23,'Gemini Output'!B:B,'Gemini Output'!E:E,"No Match Yet") -> L1 | J23: 14 | K23: Weather & Disaster | L23: Event-driven (Severity, location, response) | R23: 14 | S23: =COUNTIF(F:F,R23) -> 14
C24: 21 | D24: al | E24: 1055 | F24: =_xlfn.XLOOKUP(D24,'Gemini Output'!B:B,'Gemini Output'!C:C,"No Match Yet") -> 13 | G24: =_xlfn.XLOOKUP(D24,'Gemini Output'!B:B,'Gemini Output'!E:E,"No Match Yet") -> L1 | R24: 15 | S24: =COUNTIF(F:F,R24) -> 48
C25: 22 | D25: En | E25: 999 | F25: =_xlfn.XLOOKUP(D25,'Gemini Output'!B:B,'Gemini Output'!C:C,"No Match Yet") -> 10 | G25: =_xlfn.XLOOKUP(D25,'Gemini Output'!B:B,'Gemini Output'!E:E,"No Match Yet") -> L1
C26: 23 | D26: fue | E26: 944 | F26: =_xlfn.XLOOKUP(D26,'Gemini Output'!B:B,'Gemini Output'!C:C,"No Match Yet") -> 9 | G26: =_xlfn.XLOOKUP(D26,'Gemini Output'!B:B,'Gemini Output'!E:E,"No Match Yet") -> L1
C27: 24 | D27: no | E27: 891 | F27: =_xlfn.XLOOKUP(D27,'Gemini Output'!B:B,'Gemini Output'!C:C,"No Match Yet") -> 12 | G27: =_xlfn.XLOOKUP(D27,'Gemini Output'!B:B,'Gemini Output'!E:E,"No Match Yet") -> L1 | J27: Level ID | K27: Logic for AI | L27: Examples from your List
C28: 25 | D28: La | E28: 879 | F28: =_xlfn.XLOOKUP(D28,'Gemini Output'!B:B,'Gemini Output'!C:C,"No Match Yet") -> 12 | G28: =_xlfn.XLOOKUP(D28,'Gemini Output'!B:B,'Gemini Output'!E:E,"No Match Yet") -> L1 | J28: Basic L1 | K28: Common daily vocabulary and basic verbs. | L28: de, la, casa, ciudad, vida, agua, madre, padre, niños, calle, sol, día +4
C29: 26 | D29: más | E29: 855 | F29: =_xlfn.XLOOKUP(D29,'Gemini Output'!B:B,'Gemini Output'!C:C,"No Match Yet") -> 2 | G29: =_xlfn.XLOOKUP(D29,'Gemini Output'!B:B,'Gemini Output'!E:E,"No Match Yet") -> L1 | J29: Intermediate L2 | K29: Subject-specific nouns and active descriptive terms. | L29: equipo, película, música, teatro, fútbol, empresa, historia, naturaleza, viaje, hotel +4
C30: 27 | D30: sus | E30: 663 | F30: =_xlfn.XLOOKUP(D30,'Gemini Output'!B:B,'Gemini Output'!C:C,"No Match Yet") -> 12 | G30: =_xlfn.XLOOKUP(D30,'Gemini Output'!B:B,'Gemini Output'!E:E,"No Match Yet") -> L1 | J30: Advanced L3 | K30: Abstract concepts, technical terminology, and formal administration. | L30: administración, gestión, república, inversión, economía, técnica, infraestructura, legislación +3
C31: 28 | D31: lo | E31: 652 | F31: =_xlfn.XLOOKUP(D31,'Gemini Output'!B:B,'Gemini Output'!C:C,"No Match Yet") -> 15 | G31: =_xlfn.XLOOKUP(D31,'Gemini Output'!B:B,'Gemini Output'!E:E,"No Match Yet") -> L1
C32: 29 | D32: o | E32: 458 | F32: =_xlfn.XLOOKUP(D32,'Gemini Output'!B:B,'Gemini Output'!C:C,"No Match Yet") -> 2 | G32: =_xlfn.XLOOKUP(D32,'Gemini Output'!B:B,'Gemini Output'!E:E,"No Match Yet") -> L1
C33: 30 | D33: también | E33: 390 | F33: =_xlfn.XLOOKUP(D33,'Gemini Output'!B:B,'Gemini Output'!C:C,"No Match Yet") -> 12 | G33: =_xlfn.XLOOKUP(D33,'Gemini Output'!B:B,'Gemini Output'!E:E,"No Match Yet") -> L1
C34: 31 | D34: dos | E34: 379 | F34: =_xlfn.XLOOKUP(D34,'Gemini Output'!B:B,'Gemini Output'!C:C,"No Match Yet") -> 4 | G34: =_xlfn.XLOOKUP(D34,'Gemini Output'!B:B,'Gemini Output'!E:E,"No Match Yet") -> L1
C35: 32 | D35: Los | E35: 377 | F35: =_xlfn.XLOOKUP(D35,'Gemini Output'!B:B,'Gemini Output'!C:C,"No Match Yet") -> 12 | G35: =_xlfn.XLOOKUP(D35,'Gemini Output'!B:B,'Gemini Output'!E:E,"No Match Yet") -> L1
C36: 33 | D36: entre | E36: 373 | F36: =_xlfn.XLOOKUP(D36,'Gemini Output'!B:B,'Gemini Output'!C:C,"No Match Yet") -> 12 | G36: =_xlfn.XLOOKUP(D36,'Gemini Output'!B:B,'Gemini Output'!E:E,"No Match Yet") -> L2
C37: 34 | D37: años | E37: 362 | F37: =_xlfn.XLOOKUP(D37,'Gemini Output'!B:B,'Gemini Output'!C:C,"No Match Yet") -> 9 | G37: =_xlfn.XLOOKUP(D37,'Gemini Output'!B:B,'Gemini Output'!E:E,"No Match Yet") -> L1
C38: 35 | D38: pero | E38: 359 | F38: =_xlfn.XLOOKUP(D38,'Gemini Output'!B:B,'Gemini Output'!C:C,"No Match Yet") -> 12 | G38: =_xlfn.XLOOKUP(D38,'Gemini Output'!B:B,'Gemini Output'!E:E,"No Match Yet") -> L1
C39: 36 | D39: ha | E39: 334 | F39: =_xlfn.XLOOKUP(D39,'Gemini Output'!B:B,'Gemini Output'!C:C,"No Match Yet") -> 9 | G39: =_xlfn.XLOOKUP(D39,'Gemini Output'!B:B,'Gemini Output'!E:E,"No Match Yet") -> L3
C40: 37 | D40: este | E40: 330 | F40: =_xlfn.XLOOKUP(D40,'Gemini Output'!B:B,'Gemini Output'!C:C,"No Match Yet") -> 13 | G40: =_xlfn.XLOOKUP(D40,'Gemini Output'!B:B,'Gemini Output'!E:E,"No Match Yet") -> L1
C41: 38 | D41: sobre | E41: 313 | F41: =_xlfn.XLOOKUP(D41,'Gemini Output'!B:B,'Gemini Output'!C:C,"No Match Yet") -> 12 | G41: =_xlfn.XLOOKUP(D41,'Gemini Output'!B:B,'Gemini Output'!E:E,"No Match Yet") -> L2
C42: 39 | D42: le | E42: 311 | F42: =_xlfn.XLOOKUP(D42,'Gemini Output'!B:B,'Gemini Output'!C:C,"No Match Yet") -> 12 | G42: =_xlfn.XLOOKUP(D42,'Gemini Output'!B:B,'Gemini Output'!E:E,"No Match Yet") -> L1
...

Sheet Gemini Output
B1: Word | C1: CAT ID | D1: Category Name | E1: Level | F1: Reasoning
B2: También | C2: 12 | D2: Social Issues/Society | E2: L1 | F2: High-frequency additive conjunction used in all contexts.
B3: día | C3: 13 | D3: Lifestyle & Travel | E3: L1 | F3: Fundamental temporal noun for daily life.
B4: contra | C4: 8 | D4: Crime, Law & Justice | E4: L1 | F4: High-frequency preposition; often used for opposition or legal cases.
B5: otras | C5: 12 | D5: Social Issues/Society | E5: L1 | F5: Basic determiner for distinguishing groups or things.
B6: ese | C6: 13 | D6: Lifestyle & Travel | E6: L1 | F6: Common demonstrative pronoun used in everyday speech.
B7: De | C7: 1 | D7: Politics & Government | E7: L1 | F7: Universal preposition; essential for possession and origin.
B8: antes | C8: 9 | D8: History & Religion | E8: L1 | F8: Basic temporal marker used to establish timelines.
B9: ella | C9: 12 | D9: Social Issues/Society | E9: L1 | F9: High-frequency personal pronoun.
B10: Esta | C10: 13 | D10: Lifestyle & Travel | E10: L1 | F10: Common feminine demonstrative pronoun.
B11: Este | C11: 13 | D11: Lifestyle & Travel | E11: L1 | F11: Common masculine demonstrative pronoun.
B12: cual | C12: 7 | D12: Education | E12: L2 | F12: Relative pronoun used in more structured, formal explanations.
B13: personas | C13: 12 | D13: Social Issues/Society | E13: L1 | F13: Fundamental noun for human beings.
... B52: largo | C52: 10 | D52: Environment & Nature | E52: L1 | F52: Basic descriptive adjective for length.
B53: había | C53: 9 | E53: L1
B54: está | C54: 11 | E54: L1
B55: vez | C55: 9 | E55: L1
B56: primera | C56: 4 | E56: L1
B57: mismo | C57: 12 | E57: L1
B58: fueron | C58: 9 | E58: L1
B59: tiempo | C59: 9 | E59: L1
B60: sido | C60: 13 | E60: L1
B61: otros | C61: 12 | E61: L1
B62: ciudad | C62: 10 | E62: L1
B63: embargo | C63: 2 | E63: L2
B64: uno | C64: 4 | E64: L1
... B72: forma | C72: 6 | E72: L1
B73: Japón | C73: 13 | D73: Lifestyle & Travel | E73: L1 | F73: Common proper noun for a destination; basic geographical knowledge.
B74: Jesús | C74: 9 | D74: History & Religion | E74: L1 | F74: Central figure in religious chronology and high-frequency proper name.
B75: Posteriormente | C75: 9 | D75: History & Religion | E75: L3 | F75: Formal transition word used to establish chronological order in narratives.
B76: Unido | C76: 1 | D76: Politics & Government | E76: L2 | F76: Often used in political contexts (Reino Unido, Estados Unidos) or formal alliances.
B77: Ya | C77: 15 | D77: Misc. | E77: L1 | F77: High-frequency temporal particle; functional daily vocabulary.
B78: bases | C78: 6 | D78: Science & Tech | E78: L2 | F78: Conceptual term referring to foundations or fundamental principles of a system.
B79: curso | C79: 7 | D79: Education | E79: L2 | F79: Subject-specific noun referring to a period of study or institutional timeline.
B80: detrás | C80: 10 | D80: Environment & Nature | E80: L1 | F80: Basic spatial preposition used to describe locations.
B81: dicha | C81: 8 | D81: Crime, Law & Justice | E81: L3 | F81: Formal/archaic referential term common in legal narrative and rulings.
B82: económica | C82: 2 | D82: Economy & Finance | E82: L2 | F82: Adjective describing logical/numerical trends and financial systems.
B83: edificios | C83: 10 | D83: Environment & Nature | E83: L2 | F83: Descriptive noun for physical locations and urban ecology.
B84: eje | C84: 6 | D84: Science & Tech | E84: L3 | F84: Abstract/technical term for a central line or conceptual pivot point.
... B166: velocidad | C166: 6 | D166: Science & Tech | E166: L2 | F166: Conceptual/Technical term describing a measurable physical property.
...

Sheet Cleaning File
A1: WORD ID | B1: word | C1: Frequency | D1: CAT ID | E1: LEVEL ID | I1: WORD ID | J1: word | K1: Frequency | L1: CAT ID | M1: LEVEL ID
A2: 1 | B2: de | C2: 15226 | D2: 1 | E2: L1 | I2: 252 | J2: =_xlfn.XLOOKUP($I2,$A:$A,B:B) -> abril | K2: =_xlfn.XLOOKUP($I2,$A:$A,C:C) -> 63 | L2: =_xlfn.XLOOKUP($I2,$A:$A,D:D) -> 13 | M2: =_xlfn.XLOOKUP($I2,$A:$A,E:E) -> L1
A3: 2 | B3: la | C3: 7493 | D3: 12 | E3: L1 | I3: 896 | J3: =_xlfn.XLOOKUP($I3,$A:$A,B:B) -> Academia | K3: =_xlfn.XLOOKUP($I3,$A:$A,C:C) -> 23 | L3: =_xlfn.XLOOKUP($I3,$A:$A,D:D) -> 7 | M3: =_xlfn.XLOOKUP($I3,$A:$A,E:E) -> L2
A4: 3 | B4: en | C4: 5973 | D4: 10 | E4: L1 | I4: 990 | J4: =_xlfn.XLOOKUP($I4,$A:$A,B:B) -> acceso | K4: =_xlfn.XLOOKUP($I4,$A:$A,C:C) -> 21 | L4: =_xlfn.XLOOKUP($I4,$A:$A,D:D) -> 5 | M4: =_xlfn.XLOOKUP($I4,$A:$A,E:E) -> L2
A5: 4 | B5: el | C5: 5435 | D5: 12 | E5: L1 | I5: 905 | J5: =_xlfn.XLOOKUP($I5,$A:$A,B:B) -> accidente | K5: =_xlfn.XLOOKUP($I5,$A:$A,C:C) -> 22 | L5: =_xlfn.XLOOKUP($I5,$A:$A,D:D) -> 14 | M5: =_xlfn.XLOOKUP($I5,$A:$A,E:E) -> L2
A6: 5 | B6: y | C6: 5422 | D6: 12 | E6: L1 | I6: 486 | J6: =_xlfn.XLOOKUP($I6,$A:$A,B:B) -> acción | K6: =_xlfn.XLOOKUP($I6,$A:$A,C:C) -> 0 | L6: =_xlfn.XLOOKUP($I6,$A:$A,D:D) -> 2 | M6: =_xlfn.XLOOKUP($I6,$A:$A,E:E) -> L2
A7: 6 | B7: que | C7: 4171 | D7: 12 | E7: L1 | I7: 906 | J7: =_xlfn.XLOOKUP($I7,$A:$A,B:B) -> acerca | K7: =_xlfn.XLOOKUP($I7,$A:$A,C:C) -> 22 | L7: =_xlfn.XLOOKUP($I7,$A:$A,D:D) -> 7 | M7: =_xlfn.XLOOKUP($I7,$A:$A,E:E) -> L2
I8: 372 | J8: =_xlfn.XLOOKUP($I8,$A:$A,B:B) -> actividad | K8: =_xlfn.XLOOKUP($I8,$A:$A,C:C) -> 46 | L8: =_xlfn.XLOOKUP($I8,$A:$A,D:D) -> 13 | M8: =_xlfn.XLOOKUP($I8,$A:$A,E:E) -> L2
A9: 8 | B9: se | C9: 2845 | D9: 12 | E9: L1 | I9: 471 | J9: =_xlfn.XLOOKUP($I9,$A:$A,B:B) -> actividades | K9: =_xlfn.XLOOKUP($I9,$A:$A,C:C) -> 38 | L9: =_xlfn.XLOOKUP($I9,$A:$A,D:D) -> 13 | M9: =_xlfn.XLOOKUP($I9,$A:$A,E:E) -> L2
A10: 9 | B10: los | C10: 2800 | D10: 12 | E10: L1 | I10: 855 | J10: =_xlfn.XLOOKUP($I10,$A:$A,B:B) -> acto | K10: =_xlfn.XLOOKUP($I10,$A:$A,C:C) -> 23 | L10: =_xlfn.XLOOKUP($I10,$A:$A,D:D) -> 8 | M10: =_xlfn.XLOOKUP($I10,$A:$A,E:E) -> L2
A11: 10 | B11: del | C11: 2645 | D11: 1 | E11: L1 | I11: 729 | J11: =_xlfn.XLOOKUP($I11,$A:$A,B:B) -> actor | K11: =_xlfn.XLOOKUP($I11,$A:$A,C:C) -> 27 | L11: =_xlfn.XLOOKUP($I11,$A:$A,D:D) -> 3 | M11: =_xlfn.XLOOKUP($I11,$A:$A,E:E) -> L1
A12: 11 | B12: un | C12: 2205 | D12: 12 | E12: L1 | I12: 520 | J12: =_xlfn.XLOOKUP($I12,$A:$A,B:B) -> actual | K12: =_xlfn.XLOOKUP($I12,$A:$A,C:C) -> 35 | L12: =_xlfn.XLOOKUP($I12,$A:$A,D:D) -> 1 | M12: =_xlfn.XLOOKUP($I12,$A:$A,E:E) -> L2
A13: 12 | B13: su | C13: 2051 | D13: 5 | E13: L1 | I13: 441 | J13: =_xlfn.XLOOKUP($I13,$A:$A,B:B) -> actualidad | K13: =_xlfn.XLOOKUP($I13,$A:$A,C:C) -> 40 | L13: =_xlfn.XLOOKUP($I13,$A:$A,D:D) -> 1 | M13: =_xlfn.XLOOKUP($I13,$A:$A,E:E) -> L2
A14: 13 | B14: una | C14: 2023 | D14: 12 | E14: L1 | I14: 468 | J14: =_xlfn.XLOOKUP($I14,$A:$A,B:B) -> Actualmente | K14: =_xlfn.XLOOKUP($I14,$A:$A,C:C) -> 38 | L14: =_xlfn.XLOOKUP($I14,$A:$A,D:D) -> 1 | M14: =_xlfn.XLOOKUP($I14,$A:$A,E:E) -> L2
A15: 14 | B15: con | C15: 2014 | D15: 12 | E15: L1 | I15: 299 | J15: =_xlfn.XLOOKUP($I15,$A:$A,B:B) -> acuerdo | K15: =_xlfn.XLOOKUP($I15,$A:$A,C:C) -> 55 | L15: =_xlfn.XLOOKUP($I15,$A:$A,D:D) -> 1 | M15: =_xlfn.XLOOKUP($I15,$A:$A,E:E) -> L2
A16: 15 | B16: las | C16: 1946 | D16: 12 | E16: L1 | I16: 907 | J16: =_xlfn.XLOOKUP($I16,$A:$A,B:B) -> adelante | K16: =_xlfn.XLOOKUP($I16,$A:$A,C:C) -> 22 | L16: =_xlfn.XLOOKUP($I16,$A:$A,D:D) -> 13 | M16: =_xlfn.XLOOKUP($I16,$A:$A,E:E) -> L1
A17: 16 | B17: por | C17: 1899 | D17: 8 | E17: L1 | I17: 145 | J17: =_xlfn.XLOOKUP($I17,$A:$A,B:B) -> Además | K17: =_xlfn.XLOOKUP($I17,$A:$A,C:C) -> 94 | L17: =_xlfn.XLOOKUP($I17,$A:$A,D:D) -> 12 | M17: =_xlfn.XLOOKUP($I17,$A:$A,E:E) -> L2
A18: 17 | B18: para | C18: 1498 | D18: 5 | E18: L1 | I18: 698 | J18: =_xlfn.XLOOKUP($I18,$A:$A,B:B) -> administración | K18: =_xlfn.XLOOKUP($I18,$A:$A,C:C) -> 28 | L18: =_xlfn.XLOOKUP($I18,$A:$A,D:D) -> 1 | M18: =_xlfn.XLOOKUP($I18,$A:$A,E:E) -> L3
A19: 18 | B19: es | C19: 1206 | D19: 1 | E19: L1 | I19: 249 | J19: =_xlfn.XLOOKUP($I19,$A:$A,B:B) -> agosto | K19: =_xlfn.XLOOKUP($I19,$A:$A,C:C) -> 64 | L19: =_xlfn.XLOOKUP($I19,$A:$A,D:D) -> 13 | M19: =_xlfn.XLOOKUP($I19,$A:$A,E:E) -> L1
I20: 281 | J20: =_xlfn.XLOOKUP($I20,$A:$A,B:B) -> agua | K20: =_xlfn.XLOOKUP($I20,$A:$A,C:C) -> 57 | L20: =_xlfn.XLOOKUP($I20,$A:$A,D:D) -> 10 | M20: =_xlfn.XLOOKUP($I20,$A:$A,E:E) -> L1
A21: 20 | B21: como | C21: 1140 | D21: 12 | E21: L1 | I21: 805 | J21: =_xlfn.XLOOKUP($I21,$A:$A,B:B) -> aguas | K21: =_xlfn.XLOOKUP($I21,$A:$A,C:C) -> 25 | L21: =_xlfn.XLOOKUP($I21,$A:$A,D:D) -> 10 | M21: =_xlfn.XLOOKUP($I21,$A:$A,E:E) -> L1
A22: 21 | B22: al | C22: 1055 | D22: 13 | E22: L1 | I22: 442 | J22: =_xlfn.XLOOKUP($I22,$A:$A,B:B) -> ahora | K22: =_xlfn.XLOOKUP($I22,$A:$A,C:C) -> 40 | L22: =_xlfn.XLOOKUP($I22,$A:$A,D:D) -> 14 | M22: =_xlfn.XLOOKUP($I22,$A:$A,E:E) -> L1
I23: 699 | J23: =_xlfn.XLOOKUP($I23,$A:$A,B:B) -> aire | K23: =_xlfn.XLOOKUP($I23,$A:$A,C:C) -> 28 | L23: =_xlfn.XLOOKUP($I23,$A:$A,D:D) -> 14 | M23: =_xlfn.XLOOKUP($I23,$A:$A,E:E) -> L1
A24: 23 | B24: fue | C24: 944 | D24: 9 | E24: L1 | I24: 21 | J24: =_xlfn.XLOOKUP($I24,$A:$A,B:B) -> al | K24: =_xlfn.XLOOKUP($I24,$A:$A,C:C) -> 1055 | L24: =_xlfn.XLOOKUP($I24,$A:$A,D:D) -> 13 | M24: =_xlfn.XLOOKUP($I24,$A:$A,E:E) -> L1
A25: 24 | B25: no | C25: 891 | D25: 12 | E25: L1 | I25: 228 | J25: =_xlfn.XLOOKUP($I25,$A:$A,B:B) -> álbum | K25: =_xlfn.XLOOKUP($I25,$A:$A,C:C) -> 68 | L25: =_xlfn.XLOOKUP($I25,$A:$A,D:D) -> 3 | M25: =_xlfn.XLOOKUP($I25,$A:$A,E:E) -> L2
I26: 856 | J26: =_xlfn.XLOOKUP($I26,$A:$A,B:B) -> alemán | K26: =_xlfn.XLOOKUP($I26,$A:$A,C:C) -> 23 | L26: =_xlfn.XLOOKUP($I26,$A:$A,D:D) -> 12 | M26: =_xlfn.XLOOKUP($I26,$A:$A,E:E) -> L1
A27: 26 | B27: más | C27: 855 | D27: 2 | E27: L1 | I27: 572 | J27: =_xlfn.XLOOKUP($I27,$A:$A,B:B) -> Alemania | K27: =_xlfn.XLOOKUP($I27,$A:$A,C:C) -> 32 | L27: =_xlfn.XLOOKUP($I27,$A:$A,D:D) -> 1 | M27: =_xlfn.XLOOKUP($I27,$A:$A,E:E) -> L1
A28: 27 | B28: sus | C28: 663 | D28: 12 | E28: L1 | I28: 547 | J28: =_xlfn.XLOOKUP($I28,$A:$A,B:B) -> algo | K28: =_xlfn.XLOOKUP($I28,$A:$A,C:C) -> 34 | L28: =_xlfn.XLOOKUP($I28,$A:$A,D:D) -> 13 | M28: =_xlfn.XLOOKUP($I28,$A:$A,E:E) -> L1
A29: 28 | B29: lo | C29: 652 | D29: 15 | E29: L1 | I29: 766 | J29: =_xlfn.XLOOKUP($I29,$A:$A,B:B) -> algún | K29: =_xlfn.XLOOKUP($I29,$A:$A,C:C) -> 26 | L29: =_xlfn.XLOOKUP($I29,$A:$A,D:D) -> 15 | M29: =_xlfn.XLOOKUP($I29,$A:$A,E:E) -> L1
A30: 29 | B30: o | C30: 458 | D30: 2 | E30: L1 | I30: 579 | J30: =_xlfn.XLOOKUP($I30,$A:$A,B:B) -> alguna | K30: =_xlfn.XLOOKUP($I30,$A:$A,C:C) -> 32 | L30: =_xlfn.XLOOKUP($I30,$A:$A,D:D) -> 12 | M30: =_xlfn.XLOOKUP($I30,$A:$A,E:E) -> L1
A31: 30 | B31: también | C31: 390 | D31: 12 | E31: L1 | I31: 234 | J31: =_xlfn.XLOOKUP($I31,$A:$A,B:B) -> algunas | K31: =_xlfn.XLOOKUP($I31,$A:$A,C:C) -> 67 | L31: =_xlfn.XLOOKUP($I31,$A:$A,D:D) -> 15 | M31: =_xlfn.XLOOKUP($I31,$A:$A,E:E) -> L1
A32: 31 | B32: dos | C32: 379 | D32: 4 | E32: L1 | I32: 400 | J32: =_xlfn.XLOOKUP($I32,$A:$A,B:B) -> allí | K32: =_xlfn.XLOOKUP($I32,$A:$A,C:C) -> 0 | L32: =_xlfn.XLOOKUP($I32,$A:$A,D:D) -> 13 | M32: =_xlfn.XLOOKUP($I32,$A:$A,E:E) -> L1
I33: 275 | J33: =_xlfn.XLOOKUP($I33,$A:$A,B:B) -> alrededor | K33: =_xlfn.XLOOKUP($I33,$A:$A,C:C) -> 58 | L33: =_xlfn.XLOOKUP($I33,$A:$A,D:D) -> 10 | M33: =_xlfn.XLOOKUP($I33,$A:$A,E:E) -> L2
A34: 33 | B34: entre | C34: 373 | D34: 12 | E34: L2 | I34: 384 | J34: =_xlfn.XLOOKUP($I34,$A:$A,B:B) -> alta | K34: =_xlfn.XLOOKUP($I34,$A:$A,C:C) -> 45 | L34: =_xlfn.XLOOKUP($I34,$A:$A,D:D) -> 11 | M34: =_xlfn.XLOOKUP($I34,$A:$A,E:E) -> L1
A35: 34 | B35: años | C35: 362 | D35: 9 | E35: L1 | I35: 373 | J35: =_xlfn.XLOOKUP($I35,$A:$A,B:B) -> alto | K35: =_xlfn.XLOOKUP($I35,$A:$A,C:C) -> 46 | L35: =_xlfn.XLOOKUP($I35,$A:$A,D:D) -> 6 | M35: =_xlfn.XLOOKUP($I35,$A:$A,E:E) -> L1
A36: 35 | B36: pero | C36: 359 | D36: 12 | E36: L1 | I36: 730 | J36: =_xlfn.XLOOKUP($I36,$A:$A,B:B) -> altura | K36: =_xlfn.XLOOKUP($I36,$A:$A,C:C) -> 27 | L36: =_xlfn.XLOOKUP($I36,$A:$A,D:D) -> 10 | M36: =_xlfn.XLOOKUP($I36,$A:$A,E:E) -> L2
A37: 36 | B37: ha | C37: 334 | D37: 9 | E37: L3 | I37: 600 | J37: =_xlfn.XLOOKUP($I37,$A:$A,B:B) -> ambas | K37: =_xlfn.XLOOKUP($I37,$A:$A,C:C) -> 31 | L37: =_xlfn.XLOOKUP($I37,$A:$A,D:D) -> 12 | M37: =_xlfn.XLOOKUP($I37,$A:$A,E:E) -> L3
A38: 37 | B38: este | C38: 330 | D38: 13 | E38: L1 | I38: 310 | J38: =_xlfn.XLOOKUP($I38,$A:$A,B:B) -> ambos | K38: =_xlfn.XLOOKUP($I38,$A:$A,C:C) -> 54 | L38: =_xlfn.XLOOKUP($I38,$A:$A,D:D) -> 12 | M38: =_xlfn.XLOOKUP($I38,$A:$A,E:E) -> L2
A39: 38 | B39: sobre | C39: 313 | D39: 12 | E39: L2 | I39: 469 | J39: =_xlfn.XLOOKUP($I39,$A:$A,B:B) -> América | K39: =_xlfn.XLOOKUP($I39,$A:$A,C:C) -> 38 | L39: =_xlfn.XLOOKUP($I39,$A:$A,D:D) -> 10 | M39: =_xlfn.XLOOKUP($I39,$A:$A,E:E) -> L1
A40: 39 | B40: le | C40: 311 | D40: 12 | E40: L1 | I40: 666 | J40: =_xlfn.XLOOKUP($I40,$A:$A,B:B) -> amigos | K40: =_xlfn.XLOOKUP($I40,$A:$A,C:C) -> 29 | L40: =_xlfn.XLOOKUP($I40,$A:$A,D:D) -> 13 | M40: =_xlfn.XLOOKUP($I40,$A:$A,E:E) -> L1
...

Sheet Final output
A1: WORD ID | B1: word | C1: Frequency | D1: CAT ID | E1: LEVEL ID
A2: 1 | B2: de | C2: 15226 | D2: 1 | E2: L1
A3: 2 | B3: la | C3: 7493 | D3: 12 | E3: L1
A4: 3 | B4: en | C4: 5973 | D4: 10 | E4: L1
A5: 4 | B5: el | C5: 5435 | D5: 12 | E5: L1
A6: 5 | B6: y | C6: 5422 | D6: 12 | E6: L1
A7: 6 | B7: que | C7: 4171 | D7: 12 | E7: L1
A8: 7 | B8: se | C8: 2845 | D8: 12 | E8: L1
A9: 8 | B9: los | C9: 2800 | D9: 12 | E9: L1
A10: 9 | B10: del | C10: 2645 | D10: 1 | E10: L1
A11: 10 | B11: un | C11: 2205 | D11: 12 | E11: L1
A12: 11 | B12: su | C12: 2051 | D12: 5 | E12: L1
A13: 12 | B13: una | C13: 2023 | D13: 12 | E13: L1
... A912: 911 | B912: volvió | C912: 0 | D912: 9 | E912: L2
